Workbook

Sheet Data Source Overview
A1: Atnarko Sockeye Age data
A3: Three DFO databases were searched for Atnarko Sockeye Age data
A6: NuSEDS Query | B6: (Historical)
A7: PADS data join Conservation Units Data
A8: Filters used:
A9: Species | B9: Sockeye
A10: Waterbody Name | B10: Atnarko River
B11: Bella Coola River
A13: File name: | B13: PADS Feb 2026 download
A14: Sheet name: | B14: Data
A17: NuSEDS Query | B17: (Historical)
A18: Age Readings Data
A19: Filters used:
A20: Species | B20: Sockeye
A21: Project ID | B21: Atnarko - All
B22: Bella Coola - All
A24: File name: | B24: Age Readings Data Feb 2026 download
A25: Sheet name: | B25: Data
A28: 2021 Appears to be the cutoff between Historical (PADS & Age Readings Data), and Modern (Age Batch Lists) age data.
A30: For Historical, I compared PADS and Age Readings Data.
A31: Age Readings data appears to include all of PADS + more samples.
A32: I suggest using Age Readings data, unless someone is aware of ages being intentionally excluded from PADS. Column: Sample Source: filter for Escapement and Native Food Fishery.
A34: For 2022 forward,
A36: Age Batch List | B36: updated Aug 2026, Downloaded in Jan 2026 (other updates: June 2026)
A38: Escapement Data
A39: Filter search | B39: Atnarko
A40: Species | B40: Sockeye
A41: Project | B41: Atnarko River Escapement
A42: Repeated for each fiscal year
A44: FSC data
A45: Filter search | B45: Bella Coola
A46: Species | B46: Sockeye
A47: Project | B47: Bella Coola FN (in-river net)
A48: Repeated for each fiscal year
A50: Downloaded multiple files where necessary
A51: Please note, older data appears as an option, but no ages actually listed.
A52: Since species is filtered by project, ensure you remove stray coho from analysis. (AKA coho submitted accidentally in a sockeye project)
A54: All 2022-2026 Escapement and FSC data have been compiled into one file.
A56: File name: | B56: Age Batch Detail Aug 2026 (upto 2024 is Feb 2026 version)
A57: Sheet Name: | B57: Age Scale Read

Sheet All age data Summary
B1: Escapement | C1: Escapement | D1: Escapement | E1: FSC | F1: FSC | G1: FSC | H1: "Other" | I1: "Other" | J1: "Other"
A2: Year | B2: PADS | C2: AGE READINGS DATA | D2: Age Batch Details* | E2: PADS* | F2: AGE READINGS DATA | G2: Age Batch Details | H2: PADS | I2: AGE READINGS DATA | J2: Age Batch Details
A3: 2025 | B3: {=IFERROR(VLOOKUP(A3,'"PADS" Summary'!$A$7:$W$20,{23},0)," ")} | C3: {=IFERROR(VLOOKUP(A3,'"Age Readings Data" Summary'!$A$12:$W$28,{23},0)," ")} | D3: 324 | E3: {=IFERROR(VLOOKUP(A3,'"PADS" Summary'!$A$29:$W$47,{23},0)," ")} | F3: {=IFERROR(VLOOKUP(A3,'"Age Readings Data" Summary'!$A$32:$W$53,{23},0)," ")}
A4: 2024 | B4: {=IFERROR(VLOOKUP(A4,'"PADS" Summary'!$A$7:$W$20,{23},0)," ")} | C4: {=IFERROR(VLOOKUP(A4,'"Age Readings Data" Summary'!$A$12:$W$28,{23},0)," ")} | D4: 57 | E4: {=IFERROR(VLOOKUP(A4,'"PADS" Summary'!$A$29:$W$47,{23},0)," ")} | F4: {=IFERROR(VLOOKUP(A4,'"Age Readings Data" Summary'!$A$32:$W$53,{23},0)," ")} | G4: 10
A5: 2023 | B5: {=IFERROR(VLOOKUP(A5,'"PADS" Summary'!$A$7:$W$20,{23},0)," ")} | C5: {=IFERROR(VLOOKUP(A5,'"Age Readings Data" Summary'!$A$12:$W$28,{23},0)," ")} | D5: 25 | E5: {=IFERROR(VLOOKUP(A5,'"PADS" Summary'!$A$29:$W$47,{23},0)," ")} | F5: {=IFERROR(VLOOKUP(A5,'"Age Readings Data" Summary'!$A$32:$W$53,{23},0)," ")} | G5: 11
A6: 2022 | B6: {=IFERROR(VLOOKUP(A6,'"PADS" Summary'!$A$7:$W$20,{23},0)," ")} | C6: {=IFERROR(VLOOKUP(A6,'"Age Readings Data" Summary'!$A$12:$W$28,{23},0)," ")} | D6: 254 | E6: {=IFERROR(VLOOKUP(A6,'"PADS" Summary'!$A$29:$W$47,{23},0)," ")} | F6: {=IFERROR(VLOOKUP(A6,'"Age Readings Data" Summary'!$A$32:$W$53,{23},0)," ")} | G6: 16
A7: 2021 | B7: {=IFERROR(VLOOKUP(A7,'"PADS" Summary'!$A$7:$W$20,{23},0)," ")} | C7: {=IFERROR(VLOOKUP(A7,'"Age Readings Data" Summary'!$A$12:$W$28,{23},0)," ")} -> 0 | E7: {=IFERROR(VLOOKUP(A7,'"PADS" Summary'!$A$29:$W$47,{23},0)," ")} -> 8 | F7: {=IFERROR(VLOOKUP(A7,'"Age Readings Data" Summary'!$A$32:$W$53,{23},0)," ")} -> 0
A8: 2020 | B8: {=IFERROR(VLOOKUP(A8,'"PADS" Summary'!$A$7:$W$20,{23},0)," ")} -> 28 | C8: {=IFERROR(VLOOKUP(A8,'"Age Readings Data" Summary'!$A$12:$W$28,{23},0)," ")} -> 0 | E8: {=IFERROR(VLOOKUP(A8,'"PADS" Summary'!$A$29:$W$47,{23},0)," ")} -> 12 | F8: {=IFERROR(VLOOKUP(A8,'"Age Readings Data" Summary'!$A$32:$W$53,{23},0)," ")} -> 0
A9: 2019 | B9: {=IFERROR(VLOOKUP(A9,'"PADS" Summary'!$A$7:$W$20,{23},0)," ")} | C9: {=IFERROR(VLOOKUP(A9,'"Age Readings Data" Summary'!$A$12:$W$28,{23},0)," ")} -> 0 | E9: {=IFERROR(VLOOKUP(A9,'"PADS" Summary'!$A$29:$W$47,{23},0)," ")} -> 75 | F9: {=IFERROR(VLOOKUP(A9,'"Age Readings Data" Summary'!$A$32:$W$53,{23},0)," ")} -> 0
A10: 2018 | B10: {=IFERROR(VLOOKUP(A10,'"PADS" Summary'!$A$7:$W$20,{23},0)," ")} -> 207 | C10: {=IFERROR(VLOOKUP(A10,'"Age Readings Data" Summary'!$A$12:$W$28,{23},0)," ")} -> 0 | E10: {=IFERROR(VLOOKUP(A10,'"PADS" Summary'!$A$29:$W$47,{23},0)," ")} -> 44 | F10: {=IFERROR(VLOOKUP(A10,'"Age Readings Data" Summary'!$A$32:$W$53,{23},0)," ")} -> 0
A11: 2017 | B11: {=IFERROR(VLOOKUP(A11,'"PADS" Summary'!$A$7:$W$20,{23},0)," ")} | C11: {=IFERROR(VLOOKUP(A11,'"Age Readings Data" Summary'!$A$12:$W$28,{23},0)," ")} -> 0 | E11: {=IFERROR(VLOOKUP(A11,'"PADS" Summary'!$A$29:$W$47,{23},0)," ")} | F11: {=IFERROR(VLOOKUP(A11,'"Age Readings Data" Summary'!$A$32:$W$53,{23},0)," ")}
A12: 2016 | B12: {=IFERROR(VLOOKUP(A12,'"PADS" Summary'!$A$7:$W$20,{23},0)," ")} -> 244 | C12: {=IFERROR(VLOOKUP(A12,'"Age Readings Data" Summary'!$A$12:$W$28,{23},0)," ")} -> 0 | E12: {=IFERROR(VLOOKUP(A12,'"PADS" Summary'!$A$29:$W$47,{23},0)," ")} -> 23 | F12: {=IFERROR(VLOOKUP(A12,'"Age Readings Data" Summary'!$A$32:$W$53,{23},0)," ")} -> 0
A13: 2015 | B13: {=IFERROR(VLOOKUP(A13,'"PADS" Summary'!$A$7:$W$20,{23},0)," ")} -> 100 | C13: {=IFERROR(VLOOKUP(A13,'"Age Readings Data" Summary'!$A$12:$W$28,{23},0)," ")} -> 0 | E13: {=IFERROR(VLOOKUP(A13,'"PADS" Summary'!$A$29:$W$47,{23},0)," ")} | F13: {=IFERROR(VLOOKUP(A13,'"Age Readings Data" Summary'!$A$32:$W$53,{23},0)," ")}
A14: 2014 | B14: {=IFERROR(VLOOKUP(A14,'"PADS" Summary'!$A$7:$W$20,{23},0)," ")} -> 34 | C14: {=IFERROR(VLOOKUP(A14,'"Age Readings Data" Summary'!$A$12:$W$28,{23},0)," ")} -> 0 | E14: {=IFERROR(VLOOKUP(A14,'"PADS" Summary'!$A$29:$W$47,{23},0)," ")} -> 29 | F14: {=IFERROR(VLOOKUP(A14,'"Age Readings Data" Summary'!$A$32:$W$53,{23},0)," ")} -> 0
A15: 2013 | B15: {=IFERROR(VLOOKUP(A15,'"PADS" Summary'!$A$7:$W$20,{23},0)," ")} -> 306 | C15: {=IFERROR(VLOOKUP(A15,'"Age Readings Data" Summary'!$A$12:$W$28,{23},0)," ")} -> 0 | E15: {=IFERROR(VLOOKUP(A15,'"PADS" Summary'!$A$29:$W$47,{23},0)," ")} | F15: {=IFERROR(VLOOKUP(A15,'"Age Readings Data" Summary'!$A$32:$W$53,{23},0)," ")}
A16: 2012 | B16: {=IFERROR(VLOOKUP(A16,'"PADS" Summary'!$A$7:$W$20,{23},0)," ")} -> 263 | C16: {=IFERROR(VLOOKUP(A16,'"Age Readings Data" Summary'!$A$12:$W$28,{23},0)," ")} -> 0 | E16: {=IFERROR(VLOOKUP(A16,'"PADS" Summary'!$A$29:$W$47,{23},0)," ")} -> 29 | F16: {=IFERROR(VLOOKUP(A16,'"Age Readings Data" Summary'!$A$32:$W$53,{23},0)," ")} -> 0
A17: 2011 | B17: {=IFERROR(VLOOKUP(A17,'"PADS" Summary'!$A$7:$W$20,{23},0)," ")} -> 57 | C17: {=IFERROR(VLOOKUP(A17,'"Age Readings Data" Summary'!$A$12:$W$28,{23},0)," ")} -> 0 | E17: {=IFERROR(VLOOKUP(A17,'"PADS" Summary'!$A$29:$W$47,{23},0)," ")} -> 9 | F17: {=IFERROR(VLOOKUP(A17,'"Age Readings Data" Summary'!$A$32:$W$53,{23},0)," ")} -> 0
A18: 2010 | B18: {=IFERROR(VLOOKUP(A18,'"PADS" Summary'!$A$7:$W$20,{23},0)," ")} -> 54 | C18: {=IFERROR(VLOOKUP(A18,'"Age Readings Data" Summary'!$A$12:$W$28,{23},0)," ")} -> 0 | E18: {=IFERROR(VLOOKUP(A18,'"PADS" Summary'!$A$29:$W$47,{23},0)," ")} -> 72 | F18: {=IFERROR(VLOOKUP(A18,'"Age Readings Data" Summary'!$A$32:$W$53,{23},0)," ")} -> 0
... A20: 2008 | B20: {=IFERROR(VLOOKUP(A20,'"PADS" Summary'!$A$7:$W$20,{23},0)," ")} -> 173 | C20: {=IFERROR(VLOOKUP(A20,'"Age Readings Data" Summary'!$A$12:$W$28,{23},0)," ")} -> 0 | E20: {=IFERROR(VLOOKUP(A20,'"PADS" Summary'!$A$29:$W$47,{23},0)," ")} -> 41 | F20: {=IFERROR(VLOOKUP(A20,'"Age Readings Data" Summary'!$A$32:$W$53,{23},0)," ")} -> 0
A21: 2007 | B21: {=IFERROR(VLOOKUP(A21,'"PADS" Summary'!$A$7:$W$20,{23},0)," ")} -> 118 | C21: {=IFERROR(VLOOKUP(A21,'"Age Readings Data" Summary'!$A$12:$W$28,{23},0)," ")} -> 0 | E21: {=IFERROR(VLOOKUP(A21,'"PADS" Summary'!$A$29:$W$47,{23},0)," ")} | F21: {=IFERROR(VLOOKUP(A21,'"Age Readings Data" Summary'!$A$32:$W$53,{23},0)," ")} | H21: Hatchery, 22 | I21: Hatchery, 22
A22: 2006 | B22: {=IFERROR(VLOOKUP(A22,'"PADS" Summary'!$A$7:$W$20,{23},0)," ")} | C22: {=IFERROR(VLOOKUP(A22,'"Age Readings Data" Summary'!$A$12:$W$28,{23},0)," ")} | E22: {=IFERROR(VLOOKUP(A22,'"PADS" Summary'!$A$29:$W$47,{23},0)," ")} -> 74 | F22: {=IFERROR(VLOOKUP(A22,'"Age Readings Data" Summary'!$A$32:$W$53,{23},0)," ")} -> 0
A23: 2005 | B23: {=IFERROR(VLOOKUP(A23,'"PADS" Summary'!$A$7:$W$20,{23},0)," ")} -> 42 | C23: {=IFERROR(VLOOKUP(A23,'"Age Readings Data" Summary'!$A$12:$W$28,{23},0)," ")} -> 0 | E23: {=IFERROR(VLOOKUP(A23,'"PADS" Summary'!$A$29:$W$47,{23},0)," ")} -> 163 | F23: {=IFERROR(VLOOKUP(A23,'"Age Readings Data" Summary'!$A$32:$W$53,{23},0)," ")} -> 0
A24: 2004 | B24: {=IFERROR(VLOOKUP(A24,'"PADS" Summary'!$A$7:$W$20,{23},0)," ")} | C24: {=IFERROR(VLOOKUP(A24,'"Age Readings Data" Summary'!$A$12:$W$28,{23},0)," ")} | E24: {=IFERROR(VLOOKUP(A24,'"PADS" Summary'!$A$29:$W$47,{23},0)," ")} | F24: {=IFERROR(VLOOKUP(A24,'"Age Readings Data" Summary'!$A$32:$W$53,{23},0)," ")}
A25: 2003 | B25: {=IFERROR(VLOOKUP(A25,'"PADS" Summary'!$A$7:$W$20,{23},0)," ")} | C25: {=IFERROR(VLOOKUP(A25,'"Age Readings Data" Summary'!$A$12:$W$28,{23},0)," ")} | E25: {=IFERROR(VLOOKUP(A25,'"PADS" Summary'!$A$29:$W$47,{23},0)," ")} -> 224 | F25: {=IFERROR(VLOOKUP(A25,'"Age Readings Data" Summary'!$A$32:$W$53,{23},0)," ")} -> 0
A26: 2002 | B26: {=IFERROR(VLOOKUP(A26,'"PADS" Summary'!$A$7:$W$20,{23},0)," ")} | C26: {=IFERROR(VLOOKUP(A26,'"Age Readings Data" Summary'!$A$12:$W$28,{23},0)," ")} | E26: {=IFERROR(VLOOKUP(A26,'"PADS" Summary'!$A$29:$W$47,{23},0)," ")} | F26: {=IFERROR(VLOOKUP(A26,'"Age Readings Data" Summary'!$A$32:$W$53,{23},0)," ")}
A27: 2001 | B27: {=IFERROR(VLOOKUP(A27,'"PADS" Summary'!$A$7:$W$20,{23},0)," ")} | C27: {=IFERROR(VLOOKUP(A27,'"Age Readings Data" Summary'!$A$12:$W$28,{23},0)," ")} | E27: {=IFERROR(VLOOKUP(A27,'"PADS" Summary'!$A$29:$W$47,{23},0)," ")} | F27: {=IFERROR(VLOOKUP(A27,'"Age Readings Data" Summary'!$A$32:$W$53,{23},0)," ")}
A28: 2000 | B28: {=IFERROR(VLOOKUP(A28,'"PADS" Summary'!$A$7:$W$20,{23},0)," ")} | C28: {=IFERROR(VLOOKUP(A28,'"Age Readings Data" Summary'!$A$12:$W$28,{23},0)," ")} | E28: {=IFERROR(VLOOKUP(A28,'"PADS" Summary'!$A$29:$W$47,{23},0)," ")} | F28: {=IFERROR(VLOOKUP(A28,'"Age Readings Data" Summary'!$A$32:$W$53,{23},0)," ")} | I28: Commercial, 50
A29: 1999 | B29: {=IFERROR(VLOOKUP(A29,'"PADS" Summary'!$A$7:$W$20,{23},0)," ")} | C29: {=IFERROR(VLOOKUP(A29,'"Age Readings Data" Summary'!$A$12:$W$28,{23},0)," ")} | E29: {=IFERROR(VLOOKUP(A29,'"PADS" Summary'!$A$29:$W$47,{23},0)," ")} | F29: {=IFERROR(VLOOKUP(A29,'"Age Readings Data" Summary'!$A$32:$W$53,{23},0)," ")} -> 0
A30: 1998 | B30: {=IFERROR(VLOOKUP(A30,'"PADS" Summary'!$A$7:$W$20,{23},0)," ")} | C30: {=IFERROR(VLOOKUP(A30,'"Age Readings Data" Summary'!$A$12:$W$28,{23},0)," ")} | E30: {=IFERROR(VLOOKUP(A30,'"PADS" Summary'!$A$29:$W$47,{23},0)," ")} | F30: {=IFERROR(VLOOKUP(A30,'"Age Readings Data" Summary'!$A$32:$W$53,{23},0)," ")} -> 0 | I30: Commercial, 36
A31: 1997 | B31: {=IFERROR(VLOOKUP(A31,'"PADS" Summary'!$A$7:$W$20,{23},0)," ")} -> 148 | C31: {=IFERROR(VLOOKUP(A31,'"Age Readings Data" Summary'!$A$12:$W$28,{23},0)," ")} -> 0 | E31: {=IFERROR(VLOOKUP(A31,'"PADS" Summary'!$A$29:$W$47,{23},0)," ")} | F31: {=IFERROR(VLOOKUP(A31,'"Age Readings Data" Summary'!$A$32:$W$53,{23},0)," ")} -> 0
A32: 1996 | B32: {=IFERROR(VLOOKUP(A32,'"PADS" Summary'!$A$7:$W$20,{23},0)," ")} | C32: {=IFERROR(VLOOKUP(A32,'"Age Readings Data" Summary'!$A$12:$W$28,{23},0)," ")} | E32: {=IFERROR(VLOOKUP(A32,'"PADS" Summary'!$A$29:$W$47,{23},0)," ")} | F32: {=IFERROR(VLOOKUP(A32,'"Age Readings Data" Summary'!$A$32:$W$53,{23},0)," ")}
A33: 1995 | B33: {=IFERROR(VLOOKUP(A33,'"PADS" Summary'!$A$7:$W$20,{23},0)," ")} | C33: {=IFERROR(VLOOKUP(A33,'"Age Readings Data" Summary'!$A$12:$W$28,{23},0)," ")} | E33: {=IFERROR(VLOOKUP(A33,'"PADS" Summary'!$A$29:$W$47,{23},0)," ")} | F33: {=IFERROR(VLOOKUP(A33,'"Age Readings Data" Summary'!$A$32:$W$53,{23},0)," ")}
A34: 1994 | B34: {=IFERROR(VLOOKUP(A34,'"PADS" Summary'!$A$7:$W$20,{23},0)," ")} | C34: {=IFERROR(VLOOKUP(A34,'"Age Readings Data" Summary'!$A$12:$W$28,{23},0)," ")} | E34: {=IFERROR(VLOOKUP(A34,'"PADS" Summary'!$A$29:$W$47,{23},0)," ")} | F34: {=IFERROR(VLOOKUP(A34,'"Age Readings Data" Summary'!$A$32:$W$53,{23},0)," ")}
A35: 1993 | B35: {=IFERROR(VLOOKUP(A35,'"PADS" Summary'!$A$7:$W$20,{23},0)," ")} | C35: {=IFERROR(VLOOKUP(A35,'"Age Readings Data" Summary'!$A$12:$W$28,{23},0)," ")} | E35: {=IFERROR(VLOOKUP(A35,'"PADS" Summary'!$A$29:$W$47,{23},0)," ")} -> 10 | F35: {=IFERROR(VLOOKUP(A35,'"Age Readings Data" Summary'!$A$32:$W$53,{23},0)," ")} -> 0 | I35: Commercial, 5
A36: 1992 | B36: {=IFERROR(VLOOKUP(A36,'"PADS" Summary'!$A$7:$W$20,{23},0)," ")} | C36: {=IFERROR(VLOOKUP(A36,'"Age Readings Data" Summary'!$A$12:$W$28,{23},0)," ")} | E36: {=IFERROR(VLOOKUP(A36,'"PADS" Summary'!$A$29:$W$47,{23},0)," ")} -> 80 | F36: {=IFERROR(VLOOKUP(A36,'"Age Readings Data" Summary'!$A$32:$W$53,{23},0)," ")} -> 0
A37: 1991 | B37: {=IFERROR(VLOOKUP(A37,'"PADS" Summary'!$A$7:$W$20,{23},0)," ")} | C37: {=IFERROR(VLOOKUP(A37,'"Age Readings Data" Summary'!$A$12:$W$28,{23},0)," ")} | E37: {=IFERROR(VLOOKUP(A37,'"PADS" Summary'!$A$29:$W$47,{23},0)," ")} -> 474 | F37: {=IFERROR(VLOOKUP(A37,'"Age Readings Data" Summary'!$A$32:$W$53,{23},0)," ")} -> 0 | I37: Commercial, 200
A38: 1990 | B38: {=IFERROR(VLOOKUP(A38,'"PADS" Summary'!$A$7:$W$20,{23},0)," ")} | C38: {=IFERROR(VLOOKUP(A38,'"Age Readings Data" Summary'!$A$12:$W$28,{23},0)," ")} | E38: {=IFERROR(VLOOKUP(A38,'"PADS" Summary'!$A$29:$W$47,{23},0)," ")} -> 495 | F38: {=IFERROR(VLOOKUP(A38,'"Age Readings Data" Summary'!$A$32:$W$53,{23},0)," ")}
A39: 1989 | B39: {=IFERROR(VLOOKUP(A39,'"PADS" Summary'!$A$7:$W$20,{23},0)," ")} | C39: {=IFERROR(VLOOKUP(A39,'"Age Readings Data" Summary'!$A$12:$W$28,{23},0)," ")} | E39: {=IFERROR(VLOOKUP(A39,'"PADS" Summary'!$A$29:$W$47,{23},0)," ")} -> 148 | F39: {=IFERROR(VLOOKUP(A39,'"Age Readings Data" Summary'!$A$32:$W$53,{23},0)," ")} | H39: Sport Fishery, 5 | I39: Commercial, 131
A42: Where "n" = number of age samples available | D42: *More specific location data available | E42: *FYI, there are an additional 11 samples from FSC in 1997 - filtered out by assumed error (location). Moot point if using AGE READINGS DATA. | H42: Not suggesting "Other" are used. Simply recording for completeness from searched databases.
A43: Includes partial Ages

Sheet "PADS" Summary
A3: Count of EU Age | B3: Column Labels
A4: Row Labels | C4: 01 | D4: 02 | E4: 03 | F4: 04 | G4: 0F | H4: 10 | I4: 11 | J4: 12 | K4: 13 | L4: 14 | M4: 1F | N4: 21 | O4: 22 | P4: 23 | Q4: 2F | R4: M0 | S4: M1 | T4: M2 | U4: M3 | V4: (blank) | W4: Grand Total
A5: ATNARKO RIVER | B5: 40 | C5: 7 | D5: 125 | E5: 141 | F5: 1 | G5: 2 | H5: 1 | I5: 33 | J5: 1116 | K5: 421 | L5: 4 | M5: 25 | N5: 3 | O5: 21 | P5: 14 | Q5: 1 | S5: 2 | T5: 20 | U5: 16 | W5: 1993
A6: ESCAPEMENT | B6: 23 | C6: 7 | D6: 124 | E6: 140 | F6: 1 | G6: 1 | H6: 1 | I6: 33 | J6: 1111 | K6: 415 | L6: 4 | M6: 20 | N6: 3 | O6: 21 | P6: 14 | S6: 2 | T6: 20 | U6: 15 | W6: 1955
A7: 1997 | B7: 8 | C7: 4 | D7: 50 | E7: 11 | J7: 57 | K7: 18 | W7: 148
A8: 2005 | B8: 2 | H8: 1 | I8: 4 | J8: 22 | K8: 5 | M8: 2 | S8: 2 | T8: 3 | U8: 1 | W8: 42
A9: 2007 | B9: 4 | C9: 1 | D9: 13 | E9: 9 | J9: 25 | K9: 40 | M9: 2 | O9: 1 | P9: 6 | T9: 9 | U9: 8 | W9: 118
A10: 2008 | B10: 5 | D10: 12 | E10: 9 | I10: 2 | J10: 109 | K10: 14 | M10: 10 | O10: 1 | T10: 7 | U10: 4 | W10: 173
A11: 2009 | B11: 1 | D11: 4 | E11: 1 | I11: 1 | J11: 106 | K11: 57 | M11: 2 | N11: 1 | O11: 6 | P11: 1 | T11: 1 | W11: 181
A12: 2010 | D12: 2 | E12: 3 | J12: 27 | K12: 19 | O12: 2 | P12: 1 | W12: 54
A13: 2011 | B13: 1 | D13: 4 | E13: 20 | I13: 1 | J13: 18 | K13: 13 | W13: 57
A14: 2012 | D14: 7 | E14: 1 | I14: 2 | J14: 213 | K14: 33 | N14: 1 | O14: 4 | P14: 2 | W14: 263
A15: 2013 | B15: 1 | D15: 12 | E15: 60 | F15: 1 | I15: 9 | J15: 99 | K15: 115 | L15: 4 | O15: 1 | P15: 3 | U15: 1 | W15: 306
A16: 2014 | B16: 1 | D16: 16 | I16: 1 | J16: 6 | K16: 10 | W16: 34
A17: 2015 | D17: 2 | E17: 12 | J17: 80 | K17: 6 | W17: 100
A18: 2016 | E18: 6 | I18: 11 | J18: 170 | K18: 53 | N18: 1 | O18: 3 | W18: 244
A19: 2018 | D19: 1 | I19: 2 | J19: 166 | K19: 32 | M19: 1 | O19: 3 | P19: 1 | U19: 1 | W19: 207
A20: 2020 | C20: 2 | D20: 1 | E20: 8 | G20: 1 | J20: 13 | M20: 3 | W20: 28
A21: HATCHERY | B21: 14 | G21: 1 | M21: 5 | Q21: 1 | U21: 1 | W21: 22
A22: 2007 | B22: 14 | G22: 1 | M22: 5 | Q22: 1 | U22: 1 | W22: 22
A23: NATIVE FOOD FISHERY | D23: 1 | E23: 1 | J23: 5 | K23: 4 | W23: 11
A24: 1997 | D24: 1 | E24: 1 | J24: 5 | K24: 4 | W24: 11
A25: SPORT FISHERY | B25: 3 | K25: 2 | W25: 5
A26: 1989 | B26: 3 | K26: 2 | W26: 5
A27: BELLA COOLA RIVER | B27: 162 | C27: 1 | D27: 177 | E27: 179 | F27: 1 | G27: 1 | I27: 11 | J27: 960 | K27: 269 | L27: 1 | M27: 1 | O27: 63 | P27: 12 | R27: 1 | S27: 4 | T27: 132 | U27: 70 | W27: 2045
A28: NATIVE FOOD FISHERY | B28: 162 | C28: 1 | D28: 177 | E28: 179 | F28: 1 | G28: 1 | I28: 11 | J28: 960 | K28: 269 | L28: 1 | M28: 1 | O28: 63 | P28: 12 | R28: 1 | S28: 4 | T28: 132 | U28: 70 | W28: 2045
A29: 1989 | B29: 50 | D29: 28 | E29: 15 | I29: 3 | J29: 40 | K29: 12 | W29: 148
A30: 1990 | B30: 32 | D30: 65 | E30: 70 | F30: 1 | I30: 4 | J30: 207 | K30: 55 | O30: 2 | P30: 2 | T30: 35 | U30: 22 | W30: 495
A31: 1991 | B31: 34 | D31: 45 | E31: 42 | J31: 274 | K31: 38 | O31: 2 | T31: 23 | U31: 16 | W31: 474
A32: 1992 | B32: 2 | D32: 1 | E32: 15 | J32: 41 | K32: 20 | S32: 1 | W32: 80
A33: 1993 | B33: 2 | E33: 4 | J33: 3 | K33: 1 | W33: 10
A34: 2003 | B34: 13 | D34: 13 | E34: 6 | J34: 112 | K34: 60 | L34: 1 | O34: 6 | P34: 1 | R34: 1 | S34: 2 | T34: 6 | U34: 3 | W34: 224
A35: 2005 | B35: 9 | C35: 1 | D35: 7 | E35: 3 | I35: 1 | J35: 58 | K35: 16 | O35: 42 | P35: 7 | T35: 13 | U35: 6 | W35: 163
A36: 2006 | B36: 3 | D36: 1 | E36: 6 | J36: 38 | K36: 7 | O36: 4 | P36: 1 | T36: 10 | U36: 4 | W36: 74
A37: 2008 | B37: 2 | D37: 2 | E37: 1 | J37: 26 | K37: 3 | T37: 6 | U37: 1 | W37: 41
A38: 2009 | B38: 1 | D38: 7 | E38: 2 | J38: 12 | K38: 5 | O38: 1 | T38: 4 | U38: 3 | W38: 35
A39: 2010 | B39: 6 | D39: 1 | E39: 9 | J39: 38 | K39: 7 | O39: 1 | S39: 1 | T39: 7 | U39: 2 | W39: 72
A40: 2011 | E40: 1 | K40: 5 | U40: 3 | W40: 9
A41: 2012 | D41: 1 | J41: 22 | K41: 2 | O41: 3 | T41: 1 | W41: 29
A42: 2014 | D42: 5 | E42: 2 | I42: 2 | J42: 14 | K42: 2 | T42: 2 | U42: 2 | W42: 29
...

Sheet "Age Readings Data" Summary
A3: Count of EU Age | B3: Column Labels
A4: Row Labels | B4: 01 | C4: 02 | D4: 03 | E4: 04 | F4: 10 | G4: 11 | H4: 12 | I4: 13 | J4: 14 | K4: 21 | L4: 22 | M4: 23 | N4: Grand Total
A5: COMMERCIAL FISHERY | C5: 9 | D5: 10 | G5: 1 | H5: 242 | I5: 37 | K5: 1 | L5: 26 | M5: 4 | N5: 330
A6: 1989 | C6: 7 | D6: 1 | G6: 1 | H6: 75 | I6: 16 | L6: 9 | N6: 109
A7: 1991 | C7: 1 | D7: 6 | H7: 132 | I7: 8 | K7: 1 | L7: 10 | N7: 158
A8: 1993 | L8: 2 | N8: 2
A9: 1998 | C9: 1 | D9: 3 | H9: 6 | I9: 7 | L9: 2 | M9: 1 | N9: 20
A10: 2000 | H10: 29 | I10: 6 | L10: 3 | M10: 3 | N10: 41
A11: ESCAPEMENT | B11: 9 | C11: 174 | D11: 171 | E11: 2 | F11: 1 | G11: 55 | H11: 1758 | I11: 529 | J11: 4 | K11: 3 | L11: 25 | M11: 15 | N11: 2746
A12: 1997 | B12: 4 | C12: 50 | D12: 11 | H12: 57 | I12: 18 | N12: 140
A13: 2005 | F13: 1 | G13: 4 | H13: 22 | I13: 5 | N13: 32
A14: 2007 | B14: 1 | C14: 13 | D14: 9 | H14: 25 | I14: 40 | L14: 1 | M14: 6 | N14: 95
A15: 2008 | C15: 12 | D15: 9 | G15: 2 | H15: 109 | I15: 14 | L15: 1 | N15: 147
A16: 2009 | C16: 4 | D16: 1 | G16: 1 | H16: 106 | I16: 57 | K16: 1 | L16: 6 | M16: 1 | N16: 177
A17: 2010 | C17: 2 | D17: 3 | H17: 27 | I17: 19 | L17: 2 | M17: 1 | N17: 54
A18: 2011 | C18: 4 | D18: 20 | G18: 1 | H18: 18 | I18: 13 | N18: 56
A19: 2012 | C19: 7 | D19: 1 | G19: 2 | H19: 213 | I19: 33 | K19: 1 | L19: 4 | M19: 2 | N19: 263
A20: 2013 | C20: 12 | D20: 60 | E20: 1 | G20: 9 | H20: 99 | I20: 115 | J20: 4 | L20: 1 | M20: 3 | N20: 304
A21: 2014 | C21: 55 | D21: 11 | E21: 1 | G21: 13 | H21: 164 | I21: 15 | N21: 259
A22: 2015 | C22: 2 | D22: 12 | H22: 80 | I22: 6 | N22: 100
A23: 2016 | D23: 6 | G23: 11 | H23: 170 | I23: 53 | K23: 1 | L23: 3 | N23: 244
A24: 2017 | G24: 1 | H24: 83 | I24: 13 | L24: 2 | N24: 99
A25: 2018 | C25: 1 | G25: 2 | H25: 166 | I25: 32 | L25: 3 | M25: 1 | N25: 205
A26: 2019 | C26: 4 | D26: 9 | H26: 92 | I26: 24 | N26: 129
A27: 2020 | B27: 2 | C27: 4 | D27: 14 | G27: 3 | H27: 178 | I27: 6 | N27: 207
A28: 2021 | B28: 2 | C28: 4 | D28: 5 | G28: 6 | H28: 149 | I28: 66 | L28: 2 | M28: 1 | N28: 235
A29: NATIVE FOOD FISHERY | B29: 1 | C29: 211 | D29: 221 | E29: 1 | G29: 12 | H29: 1021 | I29: 300 | J29: 1 | L29: 69 | M29: 12 | N29: 1849
A30: 1989 | C30: 30 | D30: 15 | G30: 4 | H30: 67 | I30: 15 | L30: 5 | N30: 136
A31: 1990 | C31: 65 | D31: 70 | E31: 1 | G31: 4 | H31: 207 | I31: 55 | L31: 2 | M31: 2 | N31: 406
A32: 1991 | C32: 45 | D32: 42 | H32: 274 | I32: 38 | L32: 2 | N32: 401
A33: 1992 | C33: 1 | D33: 15 | H33: 41 | I33: 20 | N33: 77
A34: 1993 | D34: 4 | H34: 3 | I34: 1 | N34: 8
A35: 1997 | C35: 1 | D35: 1 | H35: 5 | I35: 4 | N35: 11
A36: 1998 | C36: 4 | H36: 7 | I36: 8 | N36: 19
A37: 1999 | C37: 27 | D37: 41 | H37: 22 | I37: 16 | L37: 1 | N37: 107
A38: 2003 | C38: 13 | D38: 6 | H38: 112 | I38: 60 | J38: 1 | L38: 6 | M38: 1 | N38: 199
A39: 2005 | B39: 1 | C39: 7 | D39: 3 | G39: 1 | H39: 58 | I39: 16 | L39: 42 | M39: 7 | N39: 135
A40: 2006 | C40: 1 | D40: 6 | H40: 38 | I40: 7 | L40: 4 | M40: 1 | N40: 57
A41: 2008 | C41: 2 | D41: 1 | H41: 26 | I41: 3 | N41: 32
A42: 2009 | C42: 7 | D42: 2 | H42: 12 | I42: 5 | L42: 1 | N42: 27
...

Sheet "Age Batch Details" Summary
A1: SPECIES | B1: Sockeye
A3: Count of GR AGE | B3: Column Labels
A4: Row Labels | B4: 0F | C4: 1F | D4: 2M | E4: 31 | F4: 32 | G4: 3M | H4: 41 | I4: 42 | J4: 52 | K4: 53 | L4: 63 | M4: (blank) | N4: Grand Total
A5: Atnarko River Escapement | B5: 3 | C5: 32 | D5: 5 | E5: 7 | F5: 6 | G5: 1 | H5: 11 | I5: 201 | J5: 65 | K5: 3 | L5: 2 | N5: 336
A6: 2022 | C6: 21 | D6: 3 | F6: 2 | H6: 8 | I6: 162 | J6: 53 | K6: 3 | L6: 2 | N6: 254
A7: Atnarko River | C7: 20 | D7: 2 | F7: 1 | H7: 1 | I7: 45 | J7: 14 | N7: 83
A8: S Atnarko R abv Lonesome Lk | C8: 1 | D8: 1 | H8: 1 | I8: 53 | J8: 24 | K8: 3 | L8: 2 | N8: 85
A9: S Atnarko R bel Stillwater | F9: 1 | H9: 6 | I9: 64 | J9: 15 | N9: 86
A10: 2023 | C10: 3 | F10: 2 | G10: 1 | I10: 9 | J10: 10 | N10: 25
A11: Atnarko River mainstem | F11: 1 | I11: 2 | J11: 7 | N11: 10
A12: S Atnarko R abv Lonesome Lk | I12: 1 | N12: 1
A13: S Atnarko R abv Rainbow | C13: 3 | F13: 1 | G13: 1 | I13: 6 | J13: 3 | N13: 14
A14: 2024 | B14: 3 | C14: 8 | D14: 2 | E14: 7 | F14: 2 | H14: 3 | I14: 30 | J14: 2 | N14: 57
A15: Atnarko R abv Tenas | F15: 1 | I15: 1 | N15: 2
A16: S Atnarko R abv Lonesome Lk | F16: 1 | I16: 1 | N16: 2
A17: S Atnarko R abv Rainbow | E17: 1 | H17: 1 | I17: 16 | N17: 18
A18: S Atnarko R abv Stillwater | D18: 2 | E18: 2 | H18: 2 | N18: 6
A19: S Atnarko R bel Stillwater | B19: 3 | C19: 8 | E19: 4 | I19: 12 | J19: 2 | N19: 29
A20: Bella Coola FN (in-river net) | D20: 5 | E20: 1 | G20: 5 | H20: 2 | I20: 20 | J20: 4 | N20: 37
A21: 2022 | D21: 3 | E21: 1 | G21: 2 | I21: 8 | J21: 2 | N21: 16
A22: Lower Bella Coola River | D22: 3 | E22: 1 | G22: 2 | I22: 8 | J22: 2 | N22: 16
A23: 2023 | D23: 2 | G23: 2 | I23: 6 | J23: 1 | N23: 11
A24: Bella Coola River | D24: 2 | G24: 2 | I24: 6 | J24: 1 | N24: 11
A25: 2024 | G25: 1 | H25: 2 | I25: 6 | J25: 1 | N25: 10
A26: Bella Coola River | G26: 1 | H26: 2 | I26: 6 | J26: 1 | N26: 10
A27: Grand Total | B27: 3 | C27: 32 | D27: 10 | E27: 8 | F27: 6 | G27: 6 | H27: 13 | I27: 221 | J27: 69 | K27: 3 | L27: 2 | N27: 373

Sheet Biodata Overview
A1: Atnarko Sockeye sample bio-data
A2: Summary of readily available bio-data to accompany ages.
A3: Using Container ID (Scale Book #), and Specimen Number (Scale Cell #), can match biodata to ages.
B5: Date, sex, length, clip status, location | C5: Date, sex, length. | D5: Other | G5: *Need to check with Jason about sharing/using FSC biosampling data.
A6: Year | B6: Escapement Biodata | C6: FSC Biodata* | D6: Brood Biodata
A7: 2025 | B7: Y | C7: Y | G7: These data have not been tidied for upload.
A8: 2024 | B8: Y | C8: Y
A9: 2023 | B9: Y | C9: Y
A10: 2022 | B10: Clip, location only. KM may have a copy of full biodata. | C10: Y
A11: 2021 | B11: N | C11: N
A12: 2020 | B12: Y | C12: Y | D12: Y
A13: 2019 | C13: Y
A14: 2018 | C14: Haven't looked all the way back…
A15: 2017
A16: 2016
A17: 2015
A18: 2014
A19: 2013
A20: 2012
A21: 2011
A22: 2010
A23: 2009
A24: 2008
A25: 2007
A26: 2006
... A43: 1989
